<mujoco model="arx7">
  <compiler angle="radian" meshdir="./meshes/"/>
  <option timestep="0.002" integrator="RK4" gravity="0 0 -9.806" solver="Newton" noslip_iterations="0"/>
  <size njmax="10000" nconmax="10000"/>
  <default>
    <geom contype="1" conaffinity="1" friction="0.6 0.3 0.3" rgba="0.5 0.6 0.7 1" margin="0.001" group="0"/>
    <motor gear="50" ctrllimited="true" ctrlrange="-80 80" />
    <joint limited="true" frictionloss="0.5" damping="45" armature="0.1"/>
    <position ctrllimited='true' ctrlrange='-15 15' />
  </default>

  <asset>
    <mesh name="base_link" file="chassis/base_link.STL"/>
    <mesh name="left_thigh" file="chassis/left_thigh.STL"/>
    <mesh name="left_shin" file="chassis/left_shin.STL"/>
    <mesh name="left_wheel" file="chassis/left_wheel.STL"/>
    <mesh name="right_thigh" file="chassis/right_thigh.STL"/>
    <mesh name="right_shin" file="chassis/right_shin.STL"/>
    <mesh name="right_wheel" file="chassis/right_wheel.STL"/>

    <mesh name="stair1" file="stair/stair1.STL"/>
    <mesh name="stair2" file="stair/stair2.STL"/>
    <mesh name="stair3" file="stair/stair3.STL"/>
    <mesh name="stair4" file="stair/stair4.STL"/>
    <mesh name="stair5" file="stair/stair5.STL"/>
  </asset>

  <asset>
    <texture name="grid" type="2d" builtin="checker" rgb1=".9 .8 .7" rgb2=".4 .4 .4" width="300" height="300" mark="edge" markrgb=".2 .3 .4"/>
    <material name="grid" texture="grid" texrepeat="2 2" texuniform="true" reflectance=".2"/>
  </asset>

  <visual>
    <global offwidth="1920" offheight="1080"/>
    <rgba com="0.502 1.0 0 0.5" contactforce="0.98 0.4 0.4 0.7" contactpoint="1.0 1.0 0.6 0.4" rangefinder="0 0 0 0"/>
    <!-- <rgba com="0.502 1.0 0 0.5" contactforce="0.98 0.4 0.4 0.7" contactpoint="1.0 1.0 0.6 0.4"/> -->
    <scale com="0.2" forcewidth="0.035" contactwidth="0.10" contactheight="0.04"/>
  </visual>

  <worldbody>
    <light directional="true" diffuse=".6 .6 .6" pos="10 -10 30" dir="0 0 -10"/>
    <!-- <light pos="10 -1 30" dir="1 2 -1.5" diffuse=".6 .6 .6"/> -->
    <camera name="top" pos="0. 0. 20." xyaxes="1.000 0.0 0.000 0.0 1.000 0.017"/>
    <camera name="left" pos="0. 5 0.3" xyaxes="-1. 0. 0. 0. 0. 1."/>
    <camera name="right" pos="0. -5 0.3" xyaxes="1. 0. 0. 0. 0. 1."/>
    <camera name="track" mode="trackcom" fovy="45" pos="0.5 -1. 0.35" xyaxes="0.866 0.5 0 0 0 1"/>
    <geom name="ground" type="plane" pos="0 0 0" size="20 20 0.1" material="grid"/>
    <geom name="wall1" type="box" pos="10 0 0" size="0.1 10 5" rgba=".5 .5 .5 1"/>
    <geom name="wall2" type="box" pos="-10 0 0" size="0.1 10 5" rgba=".5 .5 .5 1"/>
    <geom name="wall3" type="box" pos="0 10 0" size="10 0.1 5" rgba=".5 .5 .5 1"/>
    <geom name="wall4" type="box" pos="0 -10 0" size="10 0.1 5" rgba=".5 .5 .5 1"/>

    <geom name="t1" type="cylinder" size="0.1 0.03 0" pos="-6 6 0" rgba="1 0 0 1" contype="0" conaffinity="0"/>
    <geom name="t2" type="cylinder" size="0.1 0.03 0" pos="-3 6 0" rgba="1 0 0 1" contype="0" conaffinity="0"/>
    <geom name="t3" type="cylinder" size="0.1 0.03 0" pos="0 6 0" rgba="1 0 0 1" contype="0" conaffinity="0"/>
    <geom name="t4" type="cylinder" size="0.1 0.03 0" pos="3 6 0" rgba="1 0 0 1" contype="0" conaffinity="0"/>
    <geom name="t5" type="cylinder" size="0.1 0.03 0" pos="6 6 0" rgba="1 0 0 1" contype="0" conaffinity="0"/>
    <geom name="t6" type="cylinder" size="0.1 0.03 0" pos="-6 3 0" rgba="1 0 0 1" contype="0" conaffinity="0"/>
    <geom name="t7" type="cylinder" size="0.1 0.03 0" pos="-3 3 0" rgba="1 0 0 1" contype="0" conaffinity="0"/>
    <geom name="t8" type="cylinder" size="0.1 0.03 0" pos="0 3 0" rgba="1 0 0 1" contype="0" conaffinity="0"/>
    <geom name="t9" type="cylinder" size="0.1 0.03 0" pos="3 3 0" rgba="1 0 0 1" contype="0" conaffinity="0"/>
    <geom name="t10" type="cylinder" size="0.1 0.03 0" pos="6 3 0" rgba="1 0 0 1" contype="0" conaffinity="0"/>
    <geom name="t11" type="cylinder" size="0.1 0.03 0" pos="-6 0 0" rgba="1 0 0 1" contype="0" conaffinity="0"/>
    <geom name="t12" type="cylinder" size="0.1 0.03 0" pos="-3 0 0" rgba="1 0 0 1" contype="0" conaffinity="0"/>
    <geom name="t13" type="cylinder" size="0.1 0.03 0" pos="0 0 0" rgba="1 0 0 1" contype="0" conaffinity="0"/>
    <geom name="t14" type="cylinder" size="0.1 0.03 0" pos="3 0 0" rgba="1 0 0 1" contype="0" conaffinity="0"/>
    <geom name="t15" type="cylinder" size="0.1 0.03 0" pos="6 0 0" rgba="1 0 0 1" contype="0" conaffinity="0"/>
    <geom name="t16" type="cylinder" size="0.1 0.03 0" pos="-6 -3 0" rgba="1 0 0 1" contype="0" conaffinity="0"/>
    <geom name="t17" type="cylinder" size="0.1 0.03 0" pos="-3 -3 0" rgba="1 0 0 1" contype="0" conaffinity="0"/>
    <geom name="t18" type="cylinder" size="0.1 0.03 0" pos="0 -3 0" rgba="1 0 0 1" contype="0" conaffinity="0"/>
    <geom name="t19" type="cylinder" size="0.1 0.03 0" pos="3 -3 0" rgba="1 0 0 1" contype="0" conaffinity="0"/>
    <geom name="t20" type="cylinder" size="0.1 0.03 0" pos="6 -3 0" rgba="1 0 0 1" contype="0" conaffinity="0"/>
    <geom name="t21" type="cylinder" size="0.1 0.03 0" pos="-6 -6 0" rgba="1 0 0 1" contype="0" conaffinity="0"/>
    <geom name="t22" type="cylinder" size="0.1 0.03 0" pos="-3 -6 0" rgba="1 0 0 1" contype="0" conaffinity="0"/>
    <geom name="t23" type="cylinder" size="0.1 0.03 0" pos="0 -6 0" rgba="1 0 0 1" contype="0" conaffinity="0"/>
    <geom name="t24" type="cylinder" size="0.1 0.03 0" pos="3 -6 0" rgba="1 0 0 1" contype="0" conaffinity="0"/>
    <geom name="t25" type="cylinder" size="0.1 0.03 0" pos="6 -6 0" rgba="1 0 0 1" contype="0" conaffinity="0"/>

    <body name='target' mocap='true' pos='0 0 0'>
        <geom name='target_indicator' type="cylinder" size="0.1 0.04 0" pos="0 0 0" rgba="0 1 0 1" contype="0" conaffinity="0"/>
    </body>


    <body name="bumps1" pos="6 0 0" euler="0 0 0" mocap="true">
      <geom name="o1" type="box" pos="-.5 .5 0" size="0.5 0.5 0.03" rgba="0. 0 .5 1" conaffinity="1"/>
      <geom name="o2" type="box" pos="2.5 -1.5 0" size="0.5 0.5 0.04" rgba="0. 0 .5 1" conaffinity="1"/>
      <geom name="o3" type="box" pos="-.5 -2.5 0" size="0.5 0.5 0.02" rgba="0. 0 .5 1" conaffinity="1"/>
      <geom name="o4" type="box" pos="1.5 1.5 0" size="0.5 0.5 0.01" rgba="0. 0 .5 1" conaffinity="1"/>
      <geom name="o5" type="box" pos="-1.5 -1.5 0" size="0.5 0.5 0.03" rgba="0. 0 .5 1" conaffinity="1"/>
      <geom name="o6" type="box" pos="-1.5 .5 0" size="0.5 0.5 0.02" rgba="0. 0 .5 1" conaffinity="1"/>
      <geom name="o7" type="box" pos=".5 2.5 0" size="0.5 0.5 0.04" rgba="0. 0 .5 1" conaffinity="1"/>
      <geom name="o8" type="box" pos="1.5 -1.5 0" size="0.5 0.5 0.01" rgba="0. 0 .5 1" conaffinity="1"/>
      <geom name="o9" type="box" pos=".5 .5 0" size="0.5 0.5 0.02" rgba="0. 0 .5 1" conaffinity="1"/>
      <geom name="o10" type="box" pos="2.5 1.5 0" size="0.5 0.5 0.04" rgba="0. 0 .5 1" conaffinity="1"/>
    </body>
    <body name="bumps2" pos="0 -6 0" euler="0 0 1.57" mocap="true">
      <geom name="o21" type="box" pos="-.5 .5 0" size="0.5 0.5 0.03" rgba="0. 0 .5 1" conaffinity="1"/>
      <geom name="o22" type="box" pos="2.5 -1.5 0" size="0.5 0.5 0.04" rgba="0. 0 .5 1" conaffinity="1"/>
      <geom name="o23" type="box" pos="-.5 -2.5 0" size="0.5 0.5 0.02" rgba="0. 0 .5 1" conaffinity="1"/>
      <geom name="o24" type="box" pos="1.5 1.5 0" size="0.5 0.5 0.01" rgba="0. 0 .5 1" conaffinity="1"/>
      <geom name="o25" type="box" pos="-1.5 -1.5 0" size="0.5 0.5 0.03" rgba="0. 0 .5 1" conaffinity="1"/>
      <geom name="o26" type="box" pos="-1.5 .5 0" size="0.5 0.5 0.02" rgba="0. 0 .5 1" conaffinity="1"/>
      <geom name="o27" type="box" pos=".5 2.5 0" size="0.5 0.5 0.04" rgba="0. 0 .5 1" conaffinity="1"/>
      <geom name="o28" type="box" pos="1.5 -1.5 0" size="0.5 0.5 0.01" rgba="0. 0 .5 1" conaffinity="1"/>
      <geom name="o29" type="box" pos=".5 .5 0" size="0.5 0.5 0.02" rgba="0. 0 .5 1" conaffinity="1"/>
      <geom name="o20" type="box" pos="2.5 1.5 0" size="0.5 0.5 0.04" rgba="0. 0 .5 1" conaffinity="1"/>
    </body>
    <body name="bumps3" pos="-6 6 0" euler="0 0 -1.57" mocap="true">
      <geom name="o31" type="box" pos="-.5 .5 0" size="0.5 0.5 0.03" rgba="0. 0 .5 1" conaffinity="1"/>
      <geom name="o32" type="box" pos="2.5 -1.5 0" size="0.5 0.5 0.04" rgba="0. 0 .5 1" conaffinity="1"/>
      <geom name="o33" type="box" pos="-.5 -2.5 0" size="0.5 0.5 0.02" rgba="0. 0 .5 1" conaffinity="1"/>
      <geom name="o34" type="box" pos="1.5 1.5 0" size="0.5 0.5 0.01" rgba="0. 0 .5 1" conaffinity="1"/>
      <geom name="o35" type="box" pos="-1.5 -1.5 0" size="0.5 0.5 0.03" rgba="0. 0 .5 1" conaffinity="1"/>
      <geom name="o36" type="box" pos="-1.5 .5 0" size="0.5 0.5 0.02" rgba="0. 0 .5 1" conaffinity="1"/>
      <geom name="o37" type="box" pos=".5 2.5 0" size="0.5 0.5 0.04" rgba="0. 0 .5 1" conaffinity="1"/>
      <geom name="o38" type="box" pos="1.5 -1.5 0" size="0.5 0.5 0.01" rgba="0. 0 .5 1" conaffinity="1"/>
      <geom name="o39" type="box" pos=".5 .5 0" size="0.5 0.5 0.02" rgba="0. 0 .5 1" conaffinity="1"/>
      <geom name="o30" type="box" pos="2.5 1.5 0" size="0.5 0.5 0.04" rgba="0. 0 .5 1" conaffinity="1"/>
    </body>

    <body name='obstacles1' mocap='true' pos='0 0 0'>
      <geom name="cube1" type="box" size="0.5 .5 2" pos="1.5 0 0" rgba=".6 .6 .6 1"/>
      <geom name="cube2" type="box" size="0.5 .5 2" pos="-2 1 0" rgba=".6 .6 .6 1"/>
    </body>
    <body name='obstacles2' mocap='true' pos='6 6 0' euler='0 0 1.57'>
      <geom name="cube21" type="box" size="0.5 .5 2" pos="1.5 0 0" rgba=".6 .6 .6 1"/>
      <geom name="cube22" type="box" size="0.5 .5 2" pos="-2 1 0" rgba=".6 .6 .6 1"/>
    </body>
    <body name='obstacles3' mocap='true' pos='-6 -6 0' euler='0 0 -1.57'>
      <geom name="cube31" type="box" size="0.5 .5 2" pos="1.5 0 0" rgba=".6 .6 .6 1"/>
      <geom name="cube32" type="box" size="0.5 .5 2" pos="-1.5 0 0" rgba=".6 .6 .6 1"/>
    </body>

    <body name='platform1' mocap='true' pos='-6 0 0' euler='0 0 -1.57'>
      <geom name="p1" type="box" size="0.5 2.5 .05" pos="1.5 0 0" rgba=".6 .6 .6 1"/>
      <geom name="p2" type="box" size="0.5 2.5 .05" pos="-1.5 0 0" rgba=".6 .6 .6 1"/>
    </body>
    <body name='platform2' mocap='true' pos='0 6 0' euler='0 0 -1.57'>
      <geom name="p21" type="box" size="0.5 2.5 .05" pos="1.5 0 0" rgba=".6 .6 .6 1"/>
      <geom name="p22" type="box" size="0.5 2.5 .05" pos="-1.5 0 0" rgba=".6 .6 .6 1"/>
    </body>
    <body name='platform3' mocap='true' pos='6 -6 0' euler='0 0 0'>
      <geom name="p31" type="box" size="0.5 2.5 .05" pos="1.5 0 0" rgba=".6 .6 .6 1"/>
      <geom name="p32" type="box" size="0.5 2.5 .05" pos="-1.5 0 0" rgba=".6 .6 .6 1"/>
    </body>

    <!-- ======= ROBOT ======= -->
    <body name="base_link" pos="-1.5 0 0.35" euler="0 0 0">
      <inertial pos="0.018885 0.00062964 0.06018" quat="-0.064773 0.618315 0.0968439 0.777246" mass="4.6733" diaginertia="0.054592 0.0348635 0.0323885"/>
      <joint name="floating_base" type="free" limited="false" frictionloss=".001" damping=".01" armature="0."/>
      <geom name="base1" type="mesh" contype="0" conaffinity="0" group="1" density="0" rgba="0.75294 0 0 1" mesh="base_link"/>
      <geom name="base2" size="0.17 0.077 0.07" pos="0.02 0 0.06" type="box" rgba="0.75294 0 0 0.000987654321"/>
      <geom name="base3" size="0.048 0.0175" pos="0.017241 0.106 0.0613" quat="0.499998 -0.500002 0.5 0.5" type="cylinder" rgba="0.75294 0 0 0.000987654321"/>
      <geom name="base4" size="0.048 0.0175" pos="0.017241 -0.106 0.0613" quat="0.499998 -0.500002 0.5 0.5" type="cylinder" rgba="0.75294 0 0 0.000987654321"/>
      <site name="imu" pos="0 0 0"/>
      <!-- <site name='cam' pos='0 0 27' xyaxes=' '/> -->
      <site name="lidar01" pos="0   -.30  .15"   zaxis=".7071 -.7071 0"/>
      <site name="lidar02" pos="0   -.20  .15"   zaxis=".8660 -.5000 0"/>
      <site name="lidar03" pos="0   -.10  .15"   zaxis=".9659 -.2588 0"/>
      <site name="lidar04" pos="0   0.00  .15"   zaxis="1 0 0"/>
      <site name="lidar05" pos="0   0.10  .15"   zaxis=".9659 .2588 0"/>
      <site name="lidar06" pos="0   0.20  .15"  zaxis=".8660 .5000 0"/>
      <site name="lidar07" pos="0   0.30  .15" zaxis=".1 .1 0"/>
      <site name="lidar08" pos="0   -.30  .10" zaxis="1 0 0"/>
      <site name="lidar09" pos="0   -.20  .10" zaxis="1 0 0"/>
      <site name="lidar10" pos="0   -.10  .10" zaxis="1 0 0"/>
      <site name="lidar11" pos="0   0.00  .10" zaxis="1 0 0"/>
      <site name="lidar12" pos="0   0.10  .10" zaxis="1 0 0"/>
      <site name="lidar13" pos="0   0.20  .10" zaxis="1 0 0"/>
      <site name="lidar14" pos="0   0.30  .10" zaxis="1 0 0"/>
      <site name="lidar15" pos="0   -.30  .05" zaxis="1 0 0"/>
      <site name="lidar16" pos="0   -.20  .05" zaxis="1 0 0"/>
      <site name="lidar17" pos="0   -.10  .05" zaxis="1 0 0"/>
      <site name="lidar18" pos="0   0.00  .05" zaxis="1 0 0"/>
      <site name="lidar19" pos="0   0.10  .05" zaxis="1 0 0"/>
      <site name="lidar20" pos="0   0.20  .05" zaxis="1 0 0"/>
      <site name="lidar21" pos="0   0.30  .05" zaxis="1 0 0"/>
      <site name="lidar22" pos="0   -.30  .00" zaxis="1 0 0"/>
      <site name="lidar23" pos="0   -.20  .00" zaxis="1 0 0"/>
      <site name="lidar24" pos="0   -.10  .00" zaxis="1 0 0"/>
      <site name="lidar25" pos="0   0.00  .00" zaxis="1 0 0"/>
      <site name="lidar26" pos="0   0.10  .00" zaxis="1 0 0"/>
      <site name="lidar27" pos="0   0.20  .00" zaxis="1 0 0"/>
      <site name="lidar28" pos="0   0.30  .00" zaxis="1 0 0"/>
      <site name="lidar29" pos="0   -.30  -.05" zaxis=".9659 0 -.2588"/>
      <site name="lidar30" pos="0   -.20  -.05" zaxis=".9659 0 -.2588"/>
      <site name="lidar31" pos="0   -.10  -.05" zaxis=".9659 0 -.2588"/>
      <site name="lidar32" pos="0   0.00  -.05" zaxis=".9659 0 -.2588"/>
      <site name="lidar33" pos="0   0.10  -.05" zaxis=".9659 0 -.2588"/>
      <site name="lidar34" pos="0   0.20  -.05" zaxis=".9659 0 -.2588"/>
      <site name="lidar35" pos="0   0.30  -.05" zaxis=".9659 0 -.2588"/>
      <site name="lidar36" pos="0   -.30  -.10" zaxis=".8660 0 -.5"/>
      <site name="lidar37" pos="0   -.20  -.10" zaxis=".8660 0 -.5"/>
      <site name="lidar38" pos="0   -.10  -.10" zaxis=".8660 0 -.5"/>
      <site name="lidar39" pos="0   0.00  -.10" zaxis=".8660 0 -.5"/>
      <site name="lidar40" pos="0   0.10  -.10" zaxis=".8660 0 -.5"/>
      <site name="lidar41" pos="0   0.20  -.10" zaxis=".8660 0 -.5"/>
      <site name="lidar42" pos="0   0.30  -.10" zaxis=".8660 0 -.5"/>
      <site name="lidar43" pos="0   -.30  -.15" zaxis=".8660 0 -.5"/>
      <site name="lidar44" pos="0   -.20  -.15" zaxis=".8660 0 -.5"/>
      <site name="lidar45" pos="0   -.10  -.15" zaxis=".8660 0 -.5"/>
      <site name="lidar46" pos="0   0.00  -.15" zaxis=".8660 0 -.5"/>
      <site name="lidar47" pos="0   0.10  -.15" zaxis=".8660 0 -.5"/>
      <site name="lidar48" pos="0   0.20  -.15" zaxis=".8660 0 -.5"/>
      <site name="lidar49" pos="0   0.30  -.15" zaxis=".8660 0 -.5"/>
      <site name="lidar50" pos="0   -.30  -.20" zaxis=".8660 0 -.5"/>
      <site name="lidar51" pos="0   -.20  -.20" zaxis=".8660 0 -.5"/>
      <site name="lidar52" pos="0   -.10  -.20" zaxis=".8660 0 -.5"/>
      <site name="lidar53" pos="0   0.00  -.20" zaxis=".8660 0 -.5"/>
      <site name="lidar54" pos="0   0.10  -.20" zaxis=".8660 0 -.5"/>
      <site name="lidar55" pos="0   0.20  -.20" zaxis=".8660 0 -.5"/>
      <site name="lidar56" pos="0   0.30  -.20" zaxis=".8660 0 -.5"/>

      <body name="left_thigh" pos="0.017241 0.13399 0.0613" euler="-1.57 0 2.35">
        <inertial pos="0.17494 0.0025294 0.012308" quat="0.0283574 0.728032 0.00169629 0.684954" mass="1.3343" diaginertia="0.00985328 0.00920167 0.00123438"/>
        <joint name="left_hip" pos="0 0 0" axis="0 0 1" range="-15 15"/>
        <geom name="left_thigh1" type="mesh" contype="0" conaffinity="0" group="1" density="0" rgba="0.89804 0.91765 0 1" mesh="left_thigh"/>
        <geom name="left_thigh2" size="0.1 0.035 0.005" pos="0.085 0 0" type="box" rgba="0 0.91765 0.92941 0.000987654321"/>
        <geom name="left_thigh3" size="0.048 0.0175" pos="0.21 0 -0.02375" type="cylinder" rgba="0 0.91765 0.92941 0.000987654321"/>
        <body name="left_shin" pos="0.21 0 0.0475" euler="0 0 -1.15">
          <inertial pos="0.15612 0.00046249 0.020119" quat="-0.0169558 0.755863 -0.00997261 0.654434" mass="0.94398" diaginertia="0.00396686 0.00358627 0.000682696"/>
          <joint name="left_knee" pos="0 0 0" axis="0 0 1" range="-15 15"/>
          <geom type="mesh" contype="0" conaffinity="0" group="1" density="0" rgba="0.89804 0.91765 0 1" mesh="left_shin"/>
          <geom size="0.1 0.035 0.005" pos="0.1 0 0" type="box" rgba="0.89804 0 0.92941 0.000987654321"/>
          <body name="left_wheel" pos="0.18 0 0.0305">
            <inertial pos="0 0 0.0012686" quat="0.5 0.5 -0.5 0.5" mass="0.44583" diaginertia="0.0014254 0.00076522 0.00076522"/>
            <joint name="left_ankle" pos="0 0 0" axis="0 0 1" limited="false"/>
            <geom type="mesh" contype="0" conaffinity="0" group="1" density="0" rgba="0.75294 0 0 1" mesh="left_wheel"/>
            <geom size="0.065 0.02" type="cylinder" rgba="0 0 0.75294 0.000987654321"/>
          </body>
        </body>
      </body>
      <body name="right_thigh" pos="0.017241 -0.13501 0.0613" euler="-1.57 0 2.35">
        <inertial pos="0.17494 0.0025279 -0.012308" quat="-0.00169159 0.684955 -0.0283402 0.728032" mass="1.3343" diaginertia="0.00985329 0.00920166 0.00123441"/>
        <joint name="right_hip" pos="0 0 0" axis="0 0 1" range="-15 15"/>
        <geom name="right_thigh1" type="mesh" contype="0" conaffinity="0" group="1" density="0" rgba="0.89804 0.91765 0 1" mesh="right_thigh"/>
        <geom name="right_thigh2" size="0.1 0.035 0.005" pos="0.085 0 0" type="box" rgba="0 0.91765 0.92941 0.000987654321"/>
        <geom name="right_thigh3" size="0.048 0.0175" pos="0.21 0 0.02375" type="cylinder" rgba="0 0.91765 0.92941 0.000987654321"/>
        <body name="right_shin" pos="0.21 0 -0.0475" euler="0 0 -1.15">
          <inertial pos="0.15612 0.00046556 -0.020119" quat="0.00996675 0.654435 0.0169079 0.755863" mass="0.94398" diaginertia="0.00396686 0.00358627 0.000682701"/>
          <joint name="right_knee" pos="0 0 0" axis="0 0 1" range="-15 15"/>
          <geom type="mesh" contype="0" conaffinity="0" group="1" density="0" rgba="0.89804 0.91765 0 1" mesh="right_shin"/>
          <geom size="0.1 0.035 0.005" pos="0.1 0 0" type="box" rgba="0.89804 0 0.92941 0.000987654321"/>
          <body name="right_wheel" pos="0.18 0 -0.0305">
            <inertial pos="0 0 -0.0012686" quat="0.5 0.5 -0.5 0.5" mass="0.44583" diaginertia="0.0014254 0.00076522 0.00076522"/>
            <joint name="right_ankle" pos="0 0 0" axis="0 0 1" limited="false"/>
            <geom type="mesh" contype="0" conaffinity="0" group="1" density="0" rgba="0.75294 0 0 1" mesh="right_wheel"/>
            <geom size="0.065 0.02" type="cylinder" rgba="0 0 0.75294 0.000987654321"/>
          </body>
        </body>
      </body>
    </body>
  </worldbody>
  <actuator>
    <position name="left_hip_motor" joint="left_hip" />
    <position name="left_knee_motor" joint="left_knee"/>
    <velocity name="left_ankle_motor" joint="left_ankle" kv='.05'/>
    <position name="right_hip_motor" joint="right_hip"/>
    <position name="right_knee_motor" joint="right_knee"/>
    <velocity name="right_ankle_motor" joint="right_ankle" kv='.05'/>
  </actuator>

  <sensor>
    <rangefinder name="l01" site="lidar01"/>
    <rangefinder name="l02" site="lidar02"/>
    <rangefinder name="l03" site="lidar03"/>
    <rangefinder name="l04" site="lidar04"/>
    <rangefinder name="l05" site="lidar05"/>
    <rangefinder name="l06" site="lidar06"/>
    <rangefinder name="l07" site="lidar07"/>
    <rangefinder name="l08" site="lidar08"/>
    <rangefinder name="l09" site="lidar09"/>
    <rangefinder name="l10" site="lidar10"/>
    <rangefinder name="l11" site="lidar11"/>
    <rangefinder name="l12" site="lidar12"/>
    <rangefinder name="l13" site="lidar13"/>
    <rangefinder name="l14" site="lidar14"/>
    <rangefinder name="l15" site="lidar15"/>
    <rangefinder name="l16" site="lidar16"/>
    <rangefinder name="l17" site="lidar17"/>
    <rangefinder name="l18" site="lidar18"/>
    <rangefinder name="l19" site="lidar19"/>
    <rangefinder name="l20" site="lidar20"/>
    <rangefinder name="l21" site="lidar21"/>
    <rangefinder name="l22" site="lidar22"/>
    <rangefinder name="l23" site="lidar23"/>
    <rangefinder name="l24" site="lidar24"/>
    <rangefinder name="l25" site="lidar25"/>
    <rangefinder name="l26" site="lidar26"/>
    <rangefinder name="l27" site="lidar27"/>
    <rangefinder name="l28" site="lidar28"/>
    <rangefinder name="l29" site="lidar29"/>
    <rangefinder name="l30" site="lidar30"/>
    <rangefinder name="l31" site="lidar31"/>
    <rangefinder name="l32" site="lidar32"/>
    <rangefinder name="l33" site="lidar33"/>
    <rangefinder name="l34" site="lidar34"/>
    <rangefinder name="l35" site="lidar35"/>
    <rangefinder name="l36" site="lidar36"/>
    <rangefinder name="l37" site="lidar37"/>
    <rangefinder name="l38" site="lidar38"/>
    <rangefinder name="l39" site="lidar39"/>
    <rangefinder name="l40" site="lidar40"/>
    <rangefinder name="l41" site="lidar41"/>
    <rangefinder name="l42" site="lidar42"/>
    <rangefinder name="l43" site="lidar43"/>
    <rangefinder name="l44" site="lidar44"/>
    <rangefinder name="l45" site="lidar45"/>
    <rangefinder name="l46" site="lidar46"/>
    <rangefinder name="l47" site="lidar47"/>
    <rangefinder name="l48" site="lidar48"/>
    <rangefinder name="l49" site="lidar49"/>
    <rangefinder name="l50" site="lidar42"/>
    <rangefinder name="l51" site="lidar43"/>
    <rangefinder name="l52" site="lidar44"/>
    <rangefinder name="l53" site="lidar45"/>
    <rangefinder name="l54" site="lidar46"/>
    <rangefinder name="l55" site="lidar47"/>
    <rangefinder name="l56" site="lidar48"/>
    <!-- <camprojection name='map' site='cam'/> -->
  </sensor>

</mujoco>
